[2024-08-16 10:47:44,763] {taskinstance.py:1159} INFO - Dependencies all met for <TaskInstance: clima_process_extractor.extract_clima_files scheduled__2023-08-26T15:20:00+00:00 [queued]>
[2024-08-16 10:47:44,768] {taskinstance.py:1159} INFO - Dependencies all met for <TaskInstance: clima_process_extractor.extract_clima_files scheduled__2023-08-26T15:20:00+00:00 [queued]>
[2024-08-16 10:47:44,768] {taskinstance.py:1356} INFO - 
--------------------------------------------------------------------------------
[2024-08-16 10:47:44,769] {taskinstance.py:1357} INFO - Starting attempt 1 of 1
[2024-08-16 10:47:44,769] {taskinstance.py:1358} INFO - 
--------------------------------------------------------------------------------
[2024-08-16 10:47:44,782] {taskinstance.py:1377} INFO - Executing <Task(PythonOperator): extract_clima_files> on 2023-08-26 15:20:00+00:00
[2024-08-16 10:47:44,786] {standard_task_runner.py:52} INFO - Started process 52788 to run task
[2024-08-16 10:47:44,789] {standard_task_runner.py:79} INFO - Running: ['airflow', 'tasks', 'run', 'clima_process_extractor', 'extract_clima_files', 'scheduled__2023-08-26T15:20:00+00:00', '--job-id', '170', '--raw', '--subdir', 'DAGS_FOLDER/my_first_dag.py', '--cfg-path', '/tmp/tmp01l_nx63', '--error-file', '/tmp/tmp5zri8rbt']
[2024-08-16 10:47:44,790] {standard_task_runner.py:80} INFO - Job 170: Subtask extract_clima_files
[2024-08-16 10:47:44,837] {task_command.py:370} INFO - Running <TaskInstance: clima_process_extractor.extract_clima_files scheduled__2023-08-26T15:20:00+00:00 [running]> on host kaiwangairflow
[2024-08-16 10:47:44,861] {taskinstance.py:1889} ERROR - Task failed with exception
Traceback (most recent call last):
  File "/home/kai/Documents/airflowalura/venv/lib/python3.9/site-packages/airflow/models/taskinstance.py", line 1451, in _run_raw_task
    self._execute_task_with_callbacks(context, test_mode)
  File "/home/kai/Documents/airflowalura/venv/lib/python3.9/site-packages/airflow/models/taskinstance.py", line 1555, in _execute_task_with_callbacks
    task_orig = self.render_templates(context=context)
  File "/home/kai/Documents/airflowalura/venv/lib/python3.9/site-packages/airflow/models/taskinstance.py", line 2212, in render_templates
    rendered_task = self.task.render_template_fields(context)
  File "/home/kai/Documents/airflowalura/venv/lib/python3.9/site-packages/airflow/models/baseoperator.py", line 1185, in render_template_fields
    self._do_render_template_fields(self, self.template_fields, context, jinja_env, set())
  File "/home/kai/Documents/airflowalura/venv/lib/python3.9/site-packages/airflow/utils/session.py", line 71, in wrapper
    return func(*args, session=session, **kwargs)
  File "/home/kai/Documents/airflowalura/venv/lib/python3.9/site-packages/airflow/models/abstractoperator.py", line 344, in _do_render_template_fields
    rendered_content = self.render_template(
  File "/home/kai/Documents/airflowalura/venv/lib/python3.9/site-packages/airflow/models/abstractoperator.py", line 404, in render_template
    return {key: self.render_template(value, context, jinja_env) for key, value in value.items()}
  File "/home/kai/Documents/airflowalura/venv/lib/python3.9/site-packages/airflow/models/abstractoperator.py", line 404, in <dictcomp>
    return {key: self.render_template(value, context, jinja_env) for key, value in value.items()}
  File "/home/kai/Documents/airflowalura/venv/lib/python3.9/site-packages/airflow/models/abstractoperator.py", line 391, in render_template
    return render_template_to_string(template, context)
  File "/home/kai/Documents/airflowalura/venv/lib/python3.9/site-packages/airflow/utils/helpers.py", line 296, in render_template_to_string
    return render_template(template, context, native=False)
  File "/home/kai/Documents/airflowalura/venv/lib/python3.9/site-packages/airflow/utils/helpers.py", line 291, in render_template
    return "".join(nodes)
  File "<template>", line 12, in root
  File "/home/kai/Documents/airflowalura/venv/lib/python3.9/site-packages/jinja2/sandbox.py", line 326, in getattr
    value = getattr(obj, attribute)
  File "/home/kai/Documents/airflowalura/venv/lib/python3.9/site-packages/jinja2/runtime.py", line 910, in __getattr__
    return self._fail_with_undefined_error()
  File "/home/kai/Documents/airflowalura/venv/lib/python3.9/site-packages/jinja2/runtime.py", line 903, in _fail_with_undefined_error
    raise self._undefined_exception(self._undefined_message)
jinja2.exceptions.UndefinedError: 'data_inteval_end' is undefined
[2024-08-16 10:47:44,865] {taskinstance.py:1395} INFO - Marking task as FAILED. dag_id=clima_process_extractor, task_id=extract_clima_files, execution_date=20230826T152000, start_date=20240816T134744, end_date=20240816T134744
[2024-08-16 10:47:44,874] {standard_task_runner.py:92} ERROR - Failed to execute job 170 for task extract_clima_files ('data_inteval_end' is undefined; 52788)
[2024-08-16 10:47:44,884] {local_task_job.py:156} INFO - Task exited with return code 1
[2024-08-16 10:47:44,900] {local_task_job.py:273} INFO - 0 downstream tasks scheduled from follow-on schedule check
